Traceback (most recent call last):
  File "/opt/homebrew/Caskroom/miniforge/base/envs/cforge_env/lib/python3.9/site-packages/jupyter_cache/executors/utils.py", line 51, in single_nb_execution
    executenb(
  File "/opt/homebrew/Caskroom/miniforge/base/envs/cforge_env/lib/python3.9/site-packages/nbclient/client.py", line 1112, in execute
    return NotebookClient(nb=nb, resources=resources, km=km, **kwargs).execute()
  File "/opt/homebrew/Caskroom/miniforge/base/envs/cforge_env/lib/python3.9/site-packages/nbclient/util.py", line 74, in wrapped
    return just_run(coro(*args, **kwargs))
  File "/opt/homebrew/Caskroom/miniforge/base/envs/cforge_env/lib/python3.9/site-packages/nbclient/util.py", line 53, in just_run
    return loop.run_until_complete(coro)
  File "/opt/homebrew/Caskroom/miniforge/base/envs/cforge_env/lib/python3.9/asyncio/base_events.py", line 642, in run_until_complete
    return future.result()
  File "/opt/homebrew/Caskroom/miniforge/base/envs/cforge_env/lib/python3.9/site-packages/nbclient/client.py", line 553, in async_execute
    await self.async_execute_cell(
  File "/opt/homebrew/Caskroom/miniforge/base/envs/cforge_env/lib/python3.9/site-packages/nbclient/client.py", line 857, in async_execute_cell
    self._check_raise_for_error(cell, exec_reply)
  File "/opt/homebrew/Caskroom/miniforge/base/envs/cforge_env/lib/python3.9/site-packages/nbclient/client.py", line 760, in _check_raise_for_error
    raise CellExecutionError.from_cell_and_msg(cell, exec_reply_content)
nbclient.exceptions.CellExecutionError: An error occurred while executing the following cell:
------------------
import pandas as pd 
import numpy as np
import matplotlib.pyplot as plt
from matplotlib.pyplot import figure
import seaborn as sns
import pycountry_convert as pc
import plotly.express as px
import plotly.offline as pyo
import plotly.express as px
import plotly.io as pio
import numpy as np
#pyo.init_notebook_mode()

pio.renderers.default = 'notebook'
------------------

[0;31m---------------------------------------------------------------------------[0m
[0;31mModuleNotFoundError[0m                       Traceback (most recent call last)
[0;32m/var/folders/wv/j_lqm8yn4ndb1hvhthjcrb540000gn/T/ipykernel_16347/23591164.py[0m in [0;36m<module>[0;34m[0m
[1;32m      4[0m [0;32mfrom[0m [0mmatplotlib[0m[0;34m.[0m[0mpyplot[0m [0;32mimport[0m [0mfigure[0m[0;34m[0m[0;34m[0m[0m
[1;32m      5[0m [0;32mimport[0m [0mseaborn[0m [0;32mas[0m [0msns[0m[0;34m[0m[0;34m[0m[0m
[0;32m----> 6[0;31m [0;32mimport[0m [0mpycountry_convert[0m [0;32mas[0m [0mpc[0m[0;34m[0m[0;34m[0m[0m
[0m[1;32m      7[0m [0;32mimport[0m [0mplotly[0m[0;34m.[0m[0mexpress[0m [0;32mas[0m [0mpx[0m[0;34m[0m[0;34m[0m[0m
[1;32m      8[0m [0;32mimport[0m [0mplotly[0m[0;34m.[0m[0moffline[0m [0;32mas[0m [0mpyo[0m[0;34m[0m[0;34m[0m[0m

[0;31mModuleNotFoundError[0m: No module named 'pycountry_convert'
ModuleNotFoundError: No module named 'pycountry_convert'

